<!DOCTYPE html>
<html lang="en">

<head>
  <meta charset="UTF-8">
  <meta http-equiv="X-UA-Compatible" content="IE=edge">
  <meta name="viewport" content="width=device-width, initial-scale=1.0">
  <title>async function</title>
</head>

<body>
  <script>
    function p1() {
      return new Promise((resolve, reject) => {
        setTimeout(() => {
          console.log(1);
          resolve(100);
        }, 1000);
      })
    }

    async function asyncF1() {
      console.log(2);
      const value = await p1();
      console.log(value);
      console.log(3);
      return value;
    }
    console.log(Object.getPrototypeOf(asyncF1).constructor);
    let value = asyncF1();
    console.log(4)
    console.log(value);
    value.then((value) => {
      console.log(value)
      console.log(5);
    })

    // 异步函数的返回值如果不是Promise对象, 那么会通过Promise.resolve会将该值包装成一个Promise对象
    async function asyncF2() {
      return 'hello, world'
    }
    console.log(asyncF2());

    asyncF2().then(value => console.log(value));

    async function asyncF3() {
      throw 'async F3 抛出异常';
      return 100;
    }
    // 如果在异步函数中发生了异常, 需要通过返回的Promise的catch方式来捕获错误, 而不是用try-catch来捕获
    // 错误的处理异步函数中抛出的异常
    // try {
    //   asyncF3()
    // } catch (error) {
    //   console.log(`try-catch:${error}`);
    // }
    asyncF3().then(value => console.log(value)).catch(error => console.log(error))


    function p3() {
      return new Promise((resolve, reject) => {
        setTimeout(() => {
          reject('p3 抛出异常了')
        }, 1000);
      })
    }
    // await后面的Promise如果是reject, 如果不处理异步函数会抛出异常. 可以通过返回的Promise的catch来捕获, 也可以在异步函数内部, 通过try-catch将awiat表达式包裹起来
    async function asyncF4() {
      let value = await p3();
      console.log(value);
      // try {
      //   let value = await p3();
      //   console.log(value);
      // } catch (error) {
      //   console.log(error);
      // }
    }
    asyncF4().then(value => console.log(value), error => console.log(error));

    function p4() {
      return new Promise((resolve, reject) => {
        setTimeout(() => {
          console.log('p4 resolve');
          resolve('p4');
        }, 2000);
      })
    }
    function p5() {
      return new Promise((resolve, reject) => {
        setTimeout(() => {
          console.log('p5 resolve')
          resolve('p5');
        }, 1000);
      })
    }
    function p6() {
      return new Promise((resolve, reject) => {
        setTimeout(() => {
          reject('p6 reject');
        }, 1000);
      })
    }

    async function asyncF5() {
      const value1 = await p4();
      console.log(value1);
      const value2 = await p5();
      console.log(value2);
      return [value1, value2];
    }

    asyncF5().then(value=>{
      console.log(value);
    })

    async function asyncF6() {
      const value1 = await p4();
      const value2 = await p5();
      const value3 = await p6(); //p6返回的Promise对象的状态编程了reject, 到该函数返回的Promise对象的状态也是reject. 
      return [value1, value2, value3]
    }
    asyncF6().then(value=>console.log(value), error=>console.log(error));

    // 多个await指令并发执行
    async function asyncF7() {
      const p1 = p4();
      const p2 = p5();
      const value1 = await p1;
      const value2 = await p2;
      return [value1, value2];
    }

    asyncF7().then(value=>console.log(value));


  </script>
</body>

</html>